Workbook

Sheet Front Desk
A1: CALI DREAM GARAGE — FRONT DESK QUOTE SYSTEM
A2: Tablet-friendly intake and quoting.
A4: CUSTOMER + VEHICLE INPUTS | F4: PRICING + DECISION ENGINE | I4: ADD-ON SELECTOR | N4: PPF BUILDER
A5: Customer Name | F5: Base Labor Hours | G5: =AVERAGE(VLOOKUP(B8,'Vehicle Data'!A2:F179,3,FALSE),VLOOKUP(B8,'Vehicle Data'!A2:F179,4,FALSE)) -> 0 | I5: Add-On | J5: Include? | K5: Price | L5: Cost | N5: Section | O5: Include? | P5: Customer Price | Q5: Total | R5: Shop Cost | S5: Total
A6: Phone / Email | F6: Base Surface Area (sq ft) | G6: =AVERAGE(VLOOKUP(B8,'Vehicle Data'!A2:F179,5,FALSE),VLOOKUP(B8,'Vehicle Data'!A2:F179,6,FALSE)) -> 0 | I6: Ceramic Coating | J6: No | K6: =IF($J6="Yes",VLOOKUP($I6,AddOns!$A$2:$D$8,2,FALSE),0) -> 0 | L6: =IF($J6="Yes",VLOOKUP($I6,AddOns!$A$2:$D$8,3,FALSE),0) -> 0 | N6: Front Bumper | O6: No | P6: 800 | Q6: =IF(O6="Yes",P6,0) -> 0 | R6: 250 | S6: =IF(O6="Yes",R6,0) -> 0
A7: Company | F7: Rate per sq ft | G7: =AVERAGE(VLOOKUP(B9,Rates!A2:C3,2,FALSE),VLOOKUP(B9,Rates!A2:C3,3,FALSE)) -> 20 | I7: Window Tint | J7: Yes | K7: =IF($J7="Yes",VLOOKUP($I7,AddOns!$A$2:$D$8,2,FALSE),0) -> 400 | L7: =IF($J7="Yes",VLOOKUP($I7,AddOns!$A$2:$D$8,3,FALSE),0) -> 120 | N7: Full Hood | O7: No | P7: 900 | Q7: =IF(O7="Yes",P7,0) -> 0 | R7: 300 | S7: =IF(O7="Yes",R7,0) -> 0
A8: Vehicle | B8: Enter Vehicle | F8: Base Wrap Revenue | G8: =IFERROR(G6*G7*IF($B$10="Easy",'Shop Settings'!$B$3,IF($B$10="Standard",'Shop Settings'!$B$4,IF($B$10="Complex",'Shop Settings'!$B$5,'Shop Settings'!$B$6))),"") -> 0 | I8: Prep Fee | J8: No | K8: =IF($J8="Yes",VLOOKUP($I8,AddOns!$A$2:$D$8,2,FALSE),0) -> 0 | L8: =IF($J8="Yes",VLOOKUP($I8,AddOns!$A$2:$D$8,3,FALSE),0) -> 0 | N8: Partial Hood | O8: No | P8: 600 | Q8: =IF(O8="Yes",P8,0) -> 0 | R8: 200 | S8: =IF(O8="Yes",R8,0) -> 0
A9: Wrap Type | B9: Color Change | F9: Shop Rate | G9: ='Shop Settings'!B2 -> 110 | I9: Trim Removal | J9: No | K9: =IF($J9="Yes",VLOOKUP($I9,AddOns!$A$2:$D$8,2,FALSE),0) -> 0 | L9: =IF($J9="Yes",VLOOKUP($I9,AddOns!$A$2:$D$8,3,FALSE),0) -> 0 | N9: Fenders | O9: No | P9: 700 | Q9: =IF(O9="Yes",P9,0) -> 0 | R9: 220 | S9: =IF(O9="Yes",R9,0) -> 0
A10: Complexity | B10: Standard | F10: Labor Revenue | G10: =IFERROR(G5*G9,"") -> 0 | I10: Design Basic | J10: No | K10: =IF($J10="Yes",VLOOKUP($I10,AddOns!$A$2:$D$8,2,FALSE),0) -> 0 | L10: =IF($J10="Yes",VLOOKUP($I10,AddOns!$A$2:$D$8,3,FALSE),0) -> 0 | N10: Mirrors | O10: No | P10: 250 | Q10: =IF(O10="Yes",P10,0) -> 0 | R10: 80 | S10: =IF(O10="Yes",R10,0) -> 0
A11: Requested Finish | B11: Matte | F11: Material Cost | G11: =IFERROR(G12*'Shop Settings'!B11,"") -> 0 | I11: Design Custom | J11: No | K11: =IF($J11="Yes",VLOOKUP($I11,AddOns!$A$2:$D$8,2,FALSE),0) -> 0 | L11: =IF($J11="Yes",VLOOKUP($I11,AddOns!$A$2:$D$8,3,FALSE),0) -> 0 | N11: Rockers | O11: No | P11: 600 | Q11: =IF(O11="Yes",P11,0) -> 0 | R11: 180 | S11: =IF(O11="Yes",R11,0) -> 0
A12: Notes | F12: Material Order Qty (sq ft) | G12: =IFERROR(G6*'Shop Settings'!$B$7,"") -> 0 | I12: Design Advanced | J12: No | K12: =IF($J12="Yes",VLOOKUP($I12,AddOns!$A$2:$D$8,2,FALSE),0) -> 0 | L12: =IF($J12="Yes",VLOOKUP($I12,AddOns!$A$2:$D$8,3,FALSE),0) -> 0 | N12: PPF Customer Price | P12: =N12 -> PPF Customer Price | Q12: =SUM(Q6:Q11) -> 0 | R12: PPF Cost | S12: =SUM(S6:S11) -> 0
F13: Add-On Revenue | G13: =SUM(K6:K12) -> 400
F14: Add-On Cost | G14: =SUM(L6:L12) -> 120
F15: TOTAL SELL PRICE | G15: =IFERROR(G8+G10+G13+Q12,"") -> 400
A16: POSITIONING SCRIPT | F16: TOTAL JOB COST | G16: =IFERROR(G11+G10+G14+S12,"") -> 120
A17: Use this sheet live with customers. Select vehicle + wrap type, choose complexity honestly, toggle add-ons, and quote from the output. Target 60%+ margin. | F17: GROSS PROFIT | G17: =IFERROR(G15-G16,"") -> 280
F18: GROSS MARGIN | G18: =IFERROR(G17/G15,0) -> 0.7
F19: DECISION | G19: =IF(G18<'Shop Settings'!$B$8,"REJECT / REPRICE",IF(G18<'Shop Settings'!$B$9,"REVIEW",IF(G18<'Shop Settings'!$B$10,"GOOD","STRONG"))) -> STRONG
F20: QUOTE TIER | G20: =IF(G15="","",IF(G15<3500,"ENTRY",IF(G15<6000,"STANDARD",IF(G15<8500,"PREMIUM","FLAGSHIP")))) -> ENTRY

Sheet Vehicle Data
A1: Vehicle Table | B1: Category | C1: Labor Low | D1: Labor High | E1: SqFt Low | F1: SqFt High | G1: Notes
A2: Enter Vehicle | B2: Van | C2: 0 | D2: 0 | E2: 0 | F2: 0
A3: Ford Transit | B3: Van | C3: 22 | D3: 28 | E3: 280 | F3: 300 | G3: Fleet staple
A4: Sprinter 144 | B4: Van | C4: 24 | D4: 30 | E4: 300 | F4: 320 | G4: High demand
A5: Sprinter 170 | B5: Van | C5: 28 | D5: 36 | E5: 340 | F5: 370 | G5: Large canvas
A6: Toyota RAV4 | B6: Small SUV | C6: 16 | D6: 18 | E6: 220 | F6: 230 | G6: Efficient retail
A7: Honda CR-V | B7: Small SUV | C7: 16 | D7: 18 | E7: 220 | F7: 230 | G7: Efficient retail
A8: Tesla Model Y | B8: Small SUV | C8: 18 | D8: 20 | E8: 230 | F8: 240 | G8: Premium customer
A9: Ford Bronco Sport | B9: Small SUV | C9: 18 | D9: 20 | E9: 230 | F9: 240 | G9: Slightly more complex
A10: Toyota 4Runner | B10: Mid SUV | C10: 18 | D10: 22 | E10: 240 | F10: 250 | G10: Popular
A11: Jeep Grand Cherokee | B11: Mid SUV | C11: 18 | D11: 22 | E11: 240 | F11: 250 | G11: Popular
A12: Ford Explorer | B12: Mid SUV | C12: 18 | D12: 21 | E12: 245 | F12: 255 | G12: Balanced
A13: Land Rover Defender | B13: Mid SUV | C13: 20 | D13: 24 | E13: 250 | F13: 260 | G13: Premium complexity
A14: Chevy Tahoe | B14: Full SUV | C14: 20 | D14: 24 | E14: 260 | F14: 275 | G14: Large retail
... A36: Fleet SUV | B36: Commercial | C36: 18 | D36: 22 | E36: 240 | F36: 260 | G36: Repeat business
A37: Honda Accord | B37: General | C37: 18 | D37: 22 | E37: 240 | F37: 260
A38: Tesla Model X | B38: General | C38: 18 | D38: 22 | E38: 240 | F38: 260
A39: BMW 5 Series | B39: General | C39: 18 | D39: 22 | E39: 240 | F39: 260
A40: BMW X3 | B40: General | C40: 18 | D40: 22 | E40: 240 | F40: 260
A41: BMW X5 | B41: General | C41: 18 | D41: 22 | E41: 240 | F41: 260
A42: BMW X7 | B42: General | C42: 18 | D42: 22 | E42: 240 | F42: 260
A43: Mercedes C Class | B43: General | C43: 18 | D43: 22 | E43: 240 | F43: 260
A44: Mercedes E Class | B44: General | C44: 18 | D44: 22 | E44: 240 | F44: 260
A45: Mercedes GLC | B45: General | C45: 18 | D45: 22 | E45: 240 | F45: 260
A46: Mercedes GLE | B46: General | C46: 18 | D46: 22 | E46: 240 | F46: 260
A47: Mercedes GLS | B47: General | C47: 18 | D47: 22 | E47: 240 | F47: 260
A48: Audi A3 | B48: General | C48: 18 | D48: 22 | E48: 240 | F48: 260
... A69: Jeep Wrangler | B69: General | C69: 18 | D69: 22 | E69: 240 | F69: 260
A70: Nissan Altima | B70: Sedan | C70: 15 | D70: 17 | E70: 210 | F70: 220 | G70: Common sedan
A71: Hyundai Sonata | B71: Sedan | C71: 15 | D71: 17 | E71: 210 | F71: 220 | G71: Common sedan
A72: Kia K5 | B72: Sedan | C72: 15 | D72: 17 | E72: 210 | F72: 220 | G72: Common sedan
A73: Mazda3 Sedan | B73: Sedan | C73: 14 | D73: 16 | E73: 200 | F73: 210 | G73: Compact sedan
A74: Kia Forte | B74: Sedan | C74: 14 | D74: 16 | E74: 200 | F74: 210 | G74: Compact sedan
A75: Nissan Sentra | B75: Sedan | C75: 14 | D75: 16 | E75: 200 | F75: 210 | G75: Compact sedan
A76: VW Jetta | B76: Sedan | C76: 14 | D76: 16 | E76: 200 | F76: 210 | G76: Compact sedan
A77: Subaru Impreza | B77: Sedan | C77: 14 | D77: 16 | E77: 200 | F77: 210 | G77: Compact sedan
A78: BMW 2 Series Gran Coupe | B78: Sedan | C78: 15 | D78: 17 | E78: 205 | F78: 215 | G78: Luxury compact
A79: Mercedes CLA | B79: Sedan | C79: 15 | D79: 17 | E79: 205 | F79: 215 | G79: Luxury compact
A80: Mercedes C-Class | B80: Sedan | C80: 16 | D80: 18 | E80: 210 | F80: 220 | G80: Luxury compact
A81: Mercedes E-Class | B81: Sedan | C81: 18 | D81: 20 | E81: 230 | F81: 240 | G81: Luxury midsize
...

Sheet Rates
A1: Wrap Type | B1: Low | C1: High | D1: Mid | E1: Source
A2: Printed | B2: 18 | C2: 28 | D2: =AVERAGE(B2:C2) -> 23 | E2: From user-provided image notes
A3: Color Change | B3: 16 | C3: 24 | D3: =AVERAGE(B3:C3) -> 20

Sheet Shop Settings
A1: Setting | B1: Value | C1: Notes
A2: Default Shop Rate | B2: 110 | C2: Target range from images: $100-$130/hr
A3: Easy Job Multiplier | B3: 0.95 | C3: Discount for straight panels / fleet repeat work
A4: Standard Job Multiplier | B4: 1 | C4: Default
A5: Complex Job Multiplier | B5: 1.12 | C5: Use for tighter curves / premium difficulty
A6: Specialty Job Multiplier | B6: 1.22 | C6: Use for Wrangler, Cybertruck, exotics-like complexity
A7: Material Waste Multiplier | B7: 1.2 | C7: Order 1.3x surface area
A8: Margin Floor | B8: 0.55 | C8: Do not accept below this unless strategic
A9: Strong Margin Target | B9: 0.6 | C9: Healthy floor
A10: Premium Margin Target | B10: 0.65 | C10: Preferred target
A11: Material cost per sq ft | B11: 2.2 | C11: Adjust per material

Sheet AddOns
A1: Add-On | B1: Default Price | C1: Default Cost | D1: Notes
A2: Ceramic Coating | B2: 700 | C2: 100 | D2: High-margin
A3: Window Tint | B3: 400 | C3: 120 | D3: High-margin
A4: Prep Fee | B4: 250 | C4: 40 | D4: Operational charge
A5: Trim Removal | B5: 300 | C5: 75 | D5: Complexity / labor offset
A6: Design Basic | B6: 300 | C6: 0 | D6: Simple layout
A7: Design Custom | B7: 600 | C7: 0 | D7: Business branding
A8: Design Advanced | B8: 1200 | C8: 0 | D8: Advanced graphics

Sheet Quote Output
A1: CALI DREAM GARAGE
A2: Customer Quote
A4: CUSTOMER | E4: VEHICLE / WRAP
A5: Name | B5: ='Front Desk'!B5 -> 0 | E5: Vehicle | F5: ='Front Desk'!B8 -> Enter Vehicle
A6: Phone / Email | B6: ='Front Desk'!B6 -> 0 | E6: Wrap Type | F6: ='Front Desk'!B9 -> Color Change
A7: Company | B7: ='Front Desk'!B7 -> 0 | E7: Finish | F7: ='Front Desk'!B11 -> Matte
A9: QUOTE SUMMARY
A10: Base Wrap | B10: ='Front Desk'!G8 -> 0 | D10: SELECTED ADD-ONS
A11: Labor | B11: ='Front Desk'!G10 -> 0 | D11: =IF('Front Desk'!J6="Yes",'Front Desk'!I6,"")
A12: PPF | B12: ='Front Desk'!Q12 -> 0 | D12: =IF('Front Desk'!J7="Yes",'Front Desk'!I7,"") -> Window Tint
A13: Selected Add-Ons | B13: ='Front Desk'!G13 -> 400 | D13: =IF('Front Desk'!J8="Yes",'Front Desk'!I8,"")
A14: Total Quote | B14: ='Front Desk'!G15 -> 400 | D14: =IF('Front Desk'!J9="Yes",'Front Desk'!I9,"")
A15: Gross Profit | B15: ='Front Desk'!G17 -> 280 | D15: =IF('Front Desk'!J10="Yes",'Front Desk'!I10,"")
D16: =IF('Front Desk'!J11="Yes",'Front Desk'!I11,"")
D17: =IF('Front Desk'!J12="Yes",'Front Desk'!I12,"")
A20: TERMS
A21: Quote valid for 7 days. Final price may change if paint condition, prior wrap residue, body damage, or hidden complexity is discovered at vehicle inspection.
A27: APPROVAL
A29: Customer Signature | E29: Date
A31: __________________________ | E31: ________________

Sheet Job Tracker
A1: Job ID | B1: Date | C1: Customer | D1: Vehicle | E1: Wrap Type | F1: Quoted Price | G1: Estimated Cost | H1: GP | I1: Margin % | J1: Decision | K1: Status | L1: Actual Sell | M1: Actual Cost | N1: Actual GP | O1: Notes
A2: J-001 | C2: ='Front Desk'!B5 -> 0 | D2: ='Front Desk'!B8 -> Enter Vehicle | E2: ='Front Desk'!B9 -> Color Change | F2: ='Front Desk'!G15 -> 400 | G2: ='Front Desk'!G16 -> 120 | H2: ='Front Desk'!G17 -> 280 | I2: ='Front Desk'!G18 -> 0.7 | J2: ='Front Desk'!G19 -> STRONG | K2: Quoted
A3: ="J-"&TEXT(ROW()-1,"000") -> J-002 | H3: =IF(OR(L3="",M3=""),"",L3-M3) | I3: =IFERROR(N3/L3,"")
A4: ="J-"&TEXT(ROW()-1,"000") -> J-003 | H4: =IF(OR(L4="",M4=""),"",L4-M4) | I4: =IFERROR(N4/L4,"")
A5: ="J-"&TEXT(ROW()-1,"000") -> J-004 | H5: =IF(OR(L5="",M5=""),"",L5-M5) | I5: =IFERROR(N5/L5,"")
A6: ="J-"&TEXT(ROW()-1,"000") -> J-005 | H6: =IF(OR(L6="",M6=""),"",L6-M6) | I6: =IFERROR(N6/L6,"")
A7: ="J-"&TEXT(ROW()-1,"000") -> J-006 | H7: =IF(OR(L7="",M7=""),"",L7-M7) | I7: =IFERROR(N7/L7,"")
A8: ="J-"&TEXT(ROW()-1,"000") -> J-007 | H8: =IF(OR(L8="",M8=""),"",L8-M8) | I8: =IFERROR(N8/L8,"")
A9: ="J-"&TEXT(ROW()-1,"000") -> J-008 | H9: =IF(OR(L9="",M9=""),"",L9-M9) | I9: =IFERROR(N9/L9,"")
A10: ="J-"&TEXT(ROW()-1,"000") -> J-009 | H10: =IF(OR(L10="",M10=""),"",L10-M10) | I10: =IFERROR(N10/L10,"")
A11: ="J-"&TEXT(ROW()-1,"000") -> J-010 | H11: =IF(OR(L11="",M11=""),"",L11-M11) | I11: =IFERROR(N11/L11,"")
A12: ="J-"&TEXT(ROW()-1,"000") -> J-011 | H12: =IF(OR(L12="",M12=""),"",L12-M12) | I12: =IFERROR(N12/L12,"")
A13: ="J-"&TEXT(ROW()-1,"000") -> J-012 | H13: =IF(OR(L13="",M13=""),"",L13-M13) | I13: =IFERROR(N13/L13,"")
A14: ="J-"&TEXT(ROW()-1,"000") -> J-013 | H14: =IF(OR(L14="",M14=""),"",L14-M14) | I14: =IFERROR(N14/L14,"")
... A201: ="J-"&TEXT(ROW()-1,"000") -> J-200 | H201: =IF(OR(L201="",M201=""),"",L201-M201) | I201: =IFERROR(N201/L201,"")

Sheet Dashboard
A1: CALI DREAM GARAGE — DASHBOARD
A3: Open Quotes | C3: Booked Jobs | E3: Quoted Revenue | G3: Actual Revenue | I3: Avg Actual Margin
A4: =COUNTIF('Job Tracker'!K:K,"Quoted") -> 1 | C4: =COUNTIF('Job Tracker'!K:K,"Booked") -> 0 | E4: =SUM('Job Tracker'!F:F) -> 400 | G4: =SUM('Job Tracker'!L:L) -> 0 | I4: =IFERROR(SUM('Job Tracker'!N:N)/SUM('Job Tracker'!L:L),0) -> 0
A6: Strong Quotes | C6: Review / Reject | E6: Completed Jobs | G6: Actual GP | I6: Avg Quote Size
A7: =COUNTIF('Job Tracker'!J:J,"STRONG") -> 1 | C7: =COUNTIF('Job Tracker'!J:J,"REJECT / REPRICE")+COUNTIF('Job Tracker'!J:J,"REVIEW") -> 0 | E7: =COUNTIF('Job Tracker'!K:K,"Complete")+COUNTIF('Job Tracker'!K:K,"Delivered") -> 0 | G7: =SUM('Job Tracker'!N:N) -> 0 | I7: =IFERROR(AVERAGEIF('Job Tracker'!F:F,">0"),0) -> 400
A10: Vehicle Category | B10: Count | D10: Decision | E10: Count
A11: Commercial | B11: =COUNTIF('Vehicle Data'!B:B,A11) -> 4 | D11: STRONG | E11: =COUNTIF('Job Tracker'!J:J,D11) -> 1
A12: Van | B12: =COUNTIF('Vehicle Data'!B:B,A12) -> 17 | D12: GOOD | E12: =COUNTIF('Job Tracker'!J:J,D12) -> 0
A13: Small SUV | B13: =COUNTIF('Vehicle Data'!B:B,A13) -> 21 | D13: REVIEW | E13: =COUNTIF('Job Tracker'!J:J,D13) -> 0
A14: Mid SUV | B14: =COUNTIF('Vehicle Data'!B:B,A14) -> 20 | D14: REJECT / REPRICE | E14: =COUNTIF('Job Tracker'!J:J,D14) -> 0
A15: Full SUV | B15: =COUNTIF('Vehicle Data'!B:B,A15) -> 13
A16: Truck | B16: =COUNTIF('Vehicle Data'!B:B,A16) -> 19
A17: Sedan | B17: =COUNTIF('Vehicle Data'!B:B,A17) -> 30
A18: Specialty | B18: =COUNTIF('Vehicle Data'!B:B,A18) -> 21

Sheet Read Me
A1: How to Use
A3: 1) Go to Front Desk.
A4: 2) Enter customer info, choose the vehicle, wrap type, and complexity.
A5: 3) Toggle add-ons Yes/No.
A6: 4) Review price, cost, gross profit, margin, and decision.
A7: 5) Open Quote Output and export that sheet to PDF if needed.
A8: 6) Log accepted jobs in Job Tracker and update actual sell/cost after completion.
A9: 7) Use Dashboard to monitor revenue, GP, and job quality.
A11: Source data in Vehicle Data / Rates / Shop Settings / AddOns
